2025-03-01 08:40:40,173 - ssh-honeypot - INFO - Starting SSH honeypot
2025-03-01 08:40:40,173 - ssh-honeypot - INFO - Generating new SSH key...
2025-03-01 08:40:40,190 - ssh-honeypot - INFO - SSH Honeypot listening on port 2222
2025-03-01 08:41:01,131 - ssh-honeypot - INFO - Connection from: 127.0.0.1:50251
2025-03-01 08:41:01,132 - ssh-honeypot - ERROR - Failed to send log to Elasticsearch: NodeConfig.__init__() missing 1 required positional argument: 'scheme'
2025-03-01 08:41:01,182 - paramiko.transport - INFO - Connected (version 2.0, client OpenSSH_for_Windows_9.5)
2025-03-01 08:41:01,199 - paramiko.transport - ERROR - Socket exception: An existing connection was forcibly closed by the remote host (10054)
2025-03-01 08:41:01,199 - ssh-honeypot - ERROR - Error handling SSH connection: [WinError 10054] An existing connection was forcibly closed by the remote host
2025-03-01 08:41:08,717 - ssh-honeypot - INFO - Connection from: 127.0.0.1:50255
2025-03-01 08:41:08,717 - ssh-honeypot - ERROR - Failed to send log to Elasticsearch: NodeConfig.__init__() missing 1 required positional argument: 'scheme'
2025-03-01 08:41:08,761 - paramiko.transport - INFO - Connected (version 2.0, client OpenSSH_for_Windows_9.5)
2025-03-01 08:41:12,395 - paramiko.transport - ERROR - Socket exception: An existing connection was forcibly closed by the remote host (10054)
2025-03-01 08:41:12,395 - ssh-honeypot - ERROR - Error handling SSH connection: [WinError 10054] An existing connection was forcibly closed by the remote host
2025-03-01 08:41:14,621 - ssh-honeypot - INFO - Connection from: 127.0.0.1:50258
2025-03-01 08:41:14,621 - ssh-honeypot - ERROR - Failed to send log to Elasticsearch: NodeConfig.__init__() missing 1 required positional argument: 'scheme'
2025-03-01 08:41:14,663 - paramiko.transport - INFO - Connected (version 2.0, client OpenSSH_for_Windows_9.5)
2025-03-01 08:41:16,110 - paramiko.transport - INFO - Auth rejected (none).
2025-03-01 08:41:18,773 - ssh-honeypot - INFO - Authentication attempt: 127.0.0.1 - username:root
2025-03-01 08:41:18,773 - ssh-honeypot - ERROR - Failed to send log to Elasticsearch: NodeConfig.__init__() missing 1 required positional argument: 'scheme'
2025-03-01 08:41:18,773 - paramiko.transport - INFO - Auth rejected (password).
2025-03-01 08:41:20,255 - ssh-honeypot - INFO - Authentication attempt: 127.0.0.1 - username:test
2025-03-01 08:41:20,255 - ssh-honeypot - ERROR - Failed to send log to Elasticsearch: NodeConfig.__init__() missing 1 required positional argument: 'scheme'
2025-03-01 08:41:20,255 - paramiko.transport - INFO - Auth rejected (password).
2025-03-01 08:41:22,939 - ssh-honeypot - INFO - Authentication attempt: 127.0.0.1 - username:root1
2025-03-01 08:41:22,939 - ssh-honeypot - ERROR - Failed to send log to Elasticsearch: NodeConfig.__init__() missing 1 required positional argument: 'scheme'
2025-03-01 08:41:22,939 - paramiko.transport - INFO - Auth rejected (password).
2025-03-01 08:41:22,941 - paramiko.transport - ERROR - Socket exception: An existing connection was forcibly closed by the remote host (10054)
2025-03-01 08:41:22,942 - ssh-honeypot - INFO - No channel from 127.0.0.1:50258
2025-03-01 08:45:58,872 - ssh-honeypot - INFO - Starting SSH honeypot
2025-03-01 08:45:58,872 - ssh-honeypot - INFO - SSH Honeypot listening on port 2222
2025-03-01 08:46:06,268 - ssh-honeypot - INFO - Connection from: 127.0.0.1:50426
2025-03-01 08:46:06,269 - ssh-honeypot - ERROR - Failed to send log to Elasticsearch: NodeConfig.__init__() missing 1 required positional argument: 'scheme'
2025-03-01 08:46:06,317 - paramiko.transport - INFO - Connected (version 2.0, client OpenSSH_for_Windows_9.5)
2025-03-01 08:46:06,331 - paramiko.transport - INFO - Auth rejected (none).
2025-03-01 08:46:19,149 - ssh-honeypot - INFO - Authentication attempt: 127.0.0.1 - username:root
2025-03-01 08:46:19,149 - ssh-honeypot - ERROR - Failed to send log to Elasticsearch: NodeConfig.__init__() missing 1 required positional argument: 'scheme'
2025-03-01 08:46:19,149 - paramiko.transport - INFO - Auth rejected (password).
2025-03-01 08:46:21,578 - ssh-honeypot - INFO - Authentication attempt: 127.0.0.1 - username:password
2025-03-01 08:46:21,578 - ssh-honeypot - ERROR - Failed to send log to Elasticsearch: NodeConfig.__init__() missing 1 required positional argument: 'scheme'
2025-03-01 08:46:21,578 - paramiko.transport - INFO - Auth rejected (password).
2025-03-01 08:46:26,268 - ssh-honeypot - INFO - Authentication attempt: 127.0.0.1 - username:test2
2025-03-01 08:46:26,269 - ssh-honeypot - ERROR - Failed to send log to Elasticsearch: NodeConfig.__init__() missing 1 required positional argument: 'scheme'
2025-03-01 08:46:26,269 - paramiko.transport - INFO - Auth rejected (password).
2025-03-01 08:46:26,271 - paramiko.transport - ERROR - Socket exception: An existing connection was forcibly closed by the remote host (10054)
2025-03-01 08:46:26,271 - ssh-honeypot - INFO - No channel from 127.0.0.1:50426
2025-03-01 09:09:40,212 - ssh-honeypot - INFO - Starting SSH honeypot
2025-03-01 09:09:40,212 - ssh-honeypot - INFO - SSH Honeypot listening on port 2222
2025-03-01 09:09:59,048 - ssh-honeypot - INFO - Connection from: 127.0.0.1:51156
2025-03-01 09:09:59,128 - elastic_transport.transport - INFO - POST http://[localhosthttps://b2e7e5b202d84e938f7e48f40dd02ef2.us-central1.gcp.cloud.es.io:443]:9200/ssh-honeypot/_doc [status:N/A duration:0.078s]
2025-03-01 09:09:59,128 - elastic_transport.node_pool - WARNING - Node <Urllib3HttpNode(http://[localhosthttps://b2e7e5b202d84e938f7e48f40dd02ef2.us-central1.gcp.cloud.es.io:443]:9200)> has failed for 1 times in a row, putting on 1 second timeout
2025-03-01 09:09:59,128 - elastic_transport.transport - WARNING - Retrying request after failure (attempt 0 of 3)
Traceback (most recent call last):
  File "D:\GitHub\personal\cybersecurity-ai-assistant\.venv\Lib\site-packages\urllib3\connection.py", line 198, in _new_conn
    sock = connection.create_connection(
        (self._dns_host, self.port),
    ...<2 lines>...
        socket_options=self.socket_options,
    )
  File "D:\GitHub\personal\cybersecurity-ai-assistant\.venv\Lib\site-packages\urllib3\util\connection.py", line 60, in create_connection
    for res in socket.getaddrinfo(host, port, family, socket.SOCK_STREAM):
               ~~~~~~~~~~~~~~~~~~^^^^^^^^^^^^^^^^^^^^^^^^^^^^^^^^^^^^^^^^
  File "C:\Users\igorv\AppData\Roaming\uv\python\cpython-3.13.2-windows-x86_64-none\Lib\socket.py", line 977, in getaddrinfo
    for res in _socket.getaddrinfo(host, port, family, type, proto, flags):
               ~~~~~~~~~~~~~~~~~~~^^^^^^^^^^^^^^^^^^^^^^^^^^^^^^^^^^^^^^^^
socket.gaierror: [Errno 11001] getaddrinfo failed

The above exception was the direct cause of the following exception:

Traceback (most recent call last):
  File "D:\GitHub\personal\cybersecurity-ai-assistant\.venv\Lib\site-packages\elastic_transport\_node\_http_urllib3.py", line 167, in perform_request
    response = self.pool.urlopen(
        method,
    ...<4 lines>...
        **kw,  # type: ignore[arg-type]
    )
  File "D:\GitHub\personal\cybersecurity-ai-assistant\.venv\Lib\site-packages\urllib3\connectionpool.py", line 841, in urlopen
    retries = retries.increment(
        method, url, error=new_e, _pool=self, _stacktrace=sys.exc_info()[2]
    )
  File "D:\GitHub\personal\cybersecurity-ai-assistant\.venv\Lib\site-packages\urllib3\util\retry.py", line 449, in increment
    raise reraise(type(error), error, _stacktrace)
          ~~~~~~~^^^^^^^^^^^^^^^^^^^^^^^^^^^^^^^^^
  File "D:\GitHub\personal\cybersecurity-ai-assistant\.venv\Lib\site-packages\urllib3\util\util.py", line 39, in reraise
    raise value
  File "D:\GitHub\personal\cybersecurity-ai-assistant\.venv\Lib\site-packages\urllib3\connectionpool.py", line 787, in urlopen
    response = self._make_request(
        conn,
    ...<10 lines>...
        **response_kw,
    )
  File "D:\GitHub\personal\cybersecurity-ai-assistant\.venv\Lib\site-packages\urllib3\connectionpool.py", line 493, in _make_request
    conn.request(
    ~~~~~~~~~~~~^
        method,
        ^^^^^^^
    ...<6 lines>...
        enforce_content_length=enforce_content_length,
        ^^^^^^^^^^^^^^^^^^^^^^^^^^^^^^^^^^^^^^^^^^^^^^
    )
    ^
  File "D:\GitHub\personal\cybersecurity-ai-assistant\.venv\Lib\site-packages\urllib3\connection.py", line 445, in request
    self.endheaders()
    ~~~~~~~~~~~~~~~^^
  File "C:\Users\igorv\AppData\Roaming\uv\python\cpython-3.13.2-windows-x86_64-none\Lib\http\client.py", line 1333, in endheaders
    self._send_output(message_body, encode_chunked=encode_chunked)
    ~~~~~~~~~~~~~~~~~^^^^^^^^^^^^^^^^^^^^^^^^^^^^^^^^^^^^^^^^^^^^^
  File "C:\Users\igorv\AppData\Roaming\uv\python\cpython-3.13.2-windows-x86_64-none\Lib\http\client.py", line 1093, in _send_output
    self.send(msg)
    ~~~~~~~~~^^^^^
  File "C:\Users\igorv\AppData\Roaming\uv\python\cpython-3.13.2-windows-x86_64-none\Lib\http\client.py", line 1037, in send
    self.connect()
    ~~~~~~~~~~~~^^
  File "D:\GitHub\personal\cybersecurity-ai-assistant\.venv\Lib\site-packages\urllib3\connection.py", line 276, in connect
    self.sock = self._new_conn()
                ~~~~~~~~~~~~~~^^
  File "D:\GitHub\personal\cybersecurity-ai-assistant\.venv\Lib\site-packages\urllib3\connection.py", line 205, in _new_conn
    raise NameResolutionError(self.host, self, e) from e
urllib3.exceptions.NameResolutionError: <urllib3.connection.HTTPConnection object at 0x000001CF12A04440>: Failed to resolve 'localhosthttps://b2e7e5b202d84e938f7e48f40dd02ef2.us-central1.gcp.cloud.es.io:443' ([Errno 11001] getaddrinfo failed)

The above exception was the direct cause of the following exception:

Traceback (most recent call last):
  File "D:\GitHub\personal\cybersecurity-ai-assistant\.venv\Lib\site-packages\elastic_transport\_transport.py", line 342, in perform_request
    resp = node.perform_request(
        method,
    ...<3 lines>...
        request_timeout=request_timeout,
    )
  File "D:\GitHub\personal\cybersecurity-ai-assistant\.venv\Lib\site-packages\elastic_transport\_node\_http_urllib3.py", line 202, in perform_request
    raise err from e
elastic_transport.ConnectionError: Connection error caused by: NameResolutionError(<urllib3.connection.HTTPConnection object at 0x000001CF12A04440>: Failed to resolve 'localhosthttps://b2e7e5b202d84e938f7e48f40dd02ef2.us-central1.gcp.cloud.es.io:443' ([Errno 11001] getaddrinfo failed))
2025-03-01 09:09:59,239 - elastic_transport.transport - INFO - POST http://[localhosthttps://b2e7e5b202d84e938f7e48f40dd02ef2.us-central1.gcp.cloud.es.io:443]:9200/ssh-honeypot/_doc [status:N/A duration:0.000s]
2025-03-01 09:09:59,239 - elastic_transport.node_pool - WARNING - Node <Urllib3HttpNode(http://[localhosthttps://b2e7e5b202d84e938f7e48f40dd02ef2.us-central1.gcp.cloud.es.io:443]:9200)> has failed for 2 times in a row, putting on 2 second timeout
2025-03-01 09:09:59,239 - elastic_transport.transport - WARNING - Retrying request after failure (attempt 1 of 3)
Traceback (most recent call last):
  File "D:\GitHub\personal\cybersecurity-ai-assistant\.venv\Lib\site-packages\urllib3\connection.py", line 198, in _new_conn
    sock = connection.create_connection(
        (self._dns_host, self.port),
    ...<2 lines>...
        socket_options=self.socket_options,
    )
  File "D:\GitHub\personal\cybersecurity-ai-assistant\.venv\Lib\site-packages\urllib3\util\connection.py", line 60, in create_connection
    for res in socket.getaddrinfo(host, port, family, socket.SOCK_STREAM):
               ~~~~~~~~~~~~~~~~~~^^^^^^^^^^^^^^^^^^^^^^^^^^^^^^^^^^^^^^^^
  File "C:\Users\igorv\AppData\Roaming\uv\python\cpython-3.13.2-windows-x86_64-none\Lib\socket.py", line 977, in getaddrinfo
    for res in _socket.getaddrinfo(host, port, family, type, proto, flags):
               ~~~~~~~~~~~~~~~~~~~^^^^^^^^^^^^^^^^^^^^^^^^^^^^^^^^^^^^^^^^
socket.gaierror: [Errno 11001] getaddrinfo failed

The above exception was the direct cause of the following exception:

Traceback (most recent call last):
  File "D:\GitHub\personal\cybersecurity-ai-assistant\.venv\Lib\site-packages\elastic_transport\_node\_http_urllib3.py", line 167, in perform_request
    response = self.pool.urlopen(
        method,
    ...<4 lines>...
        **kw,  # type: ignore[arg-type]
    )
  File "D:\GitHub\personal\cybersecurity-ai-assistant\.venv\Lib\site-packages\urllib3\connectionpool.py", line 841, in urlopen
    retries = retries.increment(
        method, url, error=new_e, _pool=self, _stacktrace=sys.exc_info()[2]
    )
  File "D:\GitHub\personal\cybersecurity-ai-assistant\.venv\Lib\site-packages\urllib3\util\retry.py", line 449, in increment
    raise reraise(type(error), error, _stacktrace)
          ~~~~~~~^^^^^^^^^^^^^^^^^^^^^^^^^^^^^^^^^
  File "D:\GitHub\personal\cybersecurity-ai-assistant\.venv\Lib\site-packages\urllib3\util\util.py", line 39, in reraise
    raise value
  File "D:\GitHub\personal\cybersecurity-ai-assistant\.venv\Lib\site-packages\urllib3\connectionpool.py", line 787, in urlopen
    response = self._make_request(
        conn,
    ...<10 lines>...
        **response_kw,
    )
  File "D:\GitHub\personal\cybersecurity-ai-assistant\.venv\Lib\site-packages\urllib3\connectionpool.py", line 493, in _make_request
    conn.request(
    ~~~~~~~~~~~~^
        method,
        ^^^^^^^
    ...<6 lines>...
        enforce_content_length=enforce_content_length,
        ^^^^^^^^^^^^^^^^^^^^^^^^^^^^^^^^^^^^^^^^^^^^^^
    )
    ^
  File "D:\GitHub\personal\cybersecurity-ai-assistant\.venv\Lib\site-packages\urllib3\connection.py", line 445, in request
    self.endheaders()
    ~~~~~~~~~~~~~~~^^
  File "C:\Users\igorv\AppData\Roaming\uv\python\cpython-3.13.2-windows-x86_64-none\Lib\http\client.py", line 1333, in endheaders
    self._send_output(message_body, encode_chunked=encode_chunked)
    ~~~~~~~~~~~~~~~~~^^^^^^^^^^^^^^^^^^^^^^^^^^^^^^^^^^^^^^^^^^^^^
  File "C:\Users\igorv\AppData\Roaming\uv\python\cpython-3.13.2-windows-x86_64-none\Lib\http\client.py", line 1093, in _send_output
    self.send(msg)
    ~~~~~~~~~^^^^^
  File "C:\Users\igorv\AppData\Roaming\uv\python\cpython-3.13.2-windows-x86_64-none\Lib\http\client.py", line 1037, in send
    self.connect()
    ~~~~~~~~~~~~^^
  File "D:\GitHub\personal\cybersecurity-ai-assistant\.venv\Lib\site-packages\urllib3\connection.py", line 276, in connect
    self.sock = self._new_conn()
                ~~~~~~~~~~~~~~^^
  File "D:\GitHub\personal\cybersecurity-ai-assistant\.venv\Lib\site-packages\urllib3\connection.py", line 205, in _new_conn
    raise NameResolutionError(self.host, self, e) from e
urllib3.exceptions.NameResolutionError: <urllib3.connection.HTTPConnection object at 0x000001CF12A40050>: Failed to resolve 'localhosthttps://b2e7e5b202d84e938f7e48f40dd02ef2.us-central1.gcp.cloud.es.io:443' ([Errno 11001] getaddrinfo failed)

The above exception was the direct cause of the following exception:

Traceback (most recent call last):
  File "D:\GitHub\personal\cybersecurity-ai-assistant\.venv\Lib\site-packages\elastic_transport\_transport.py", line 342, in perform_request
    resp = node.perform_request(
        method,
    ...<3 lines>...
        request_timeout=request_timeout,
    )
  File "D:\GitHub\personal\cybersecurity-ai-assistant\.venv\Lib\site-packages\elastic_transport\_node\_http_urllib3.py", line 202, in perform_request
    raise err from e
elastic_transport.ConnectionError: Connection error caused by: NameResolutionError(<urllib3.connection.HTTPConnection object at 0x000001CF12A40050>: Failed to resolve 'localhosthttps://b2e7e5b202d84e938f7e48f40dd02ef2.us-central1.gcp.cloud.es.io:443' ([Errno 11001] getaddrinfo failed))
2025-03-01 09:09:59,242 - elastic_transport.transport - INFO - POST http://[localhosthttps://b2e7e5b202d84e938f7e48f40dd02ef2.us-central1.gcp.cloud.es.io:443]:9200/ssh-honeypot/_doc [status:N/A duration:0.000s]
2025-03-01 09:09:59,242 - elastic_transport.node_pool - WARNING - Node <Urllib3HttpNode(http://[localhosthttps://b2e7e5b202d84e938f7e48f40dd02ef2.us-central1.gcp.cloud.es.io:443]:9200)> has failed for 3 times in a row, putting on 4 second timeout
2025-03-01 09:09:59,242 - elastic_transport.transport - WARNING - Retrying request after failure (attempt 2 of 3)
Traceback (most recent call last):
  File "D:\GitHub\personal\cybersecurity-ai-assistant\.venv\Lib\site-packages\urllib3\connection.py", line 198, in _new_conn
    sock = connection.create_connection(
        (self._dns_host, self.port),
    ...<2 lines>...
        socket_options=self.socket_options,
    )
  File "D:\GitHub\personal\cybersecurity-ai-assistant\.venv\Lib\site-packages\urllib3\util\connection.py", line 60, in create_connection
    for res in socket.getaddrinfo(host, port, family, socket.SOCK_STREAM):
               ~~~~~~~~~~~~~~~~~~^^^^^^^^^^^^^^^^^^^^^^^^^^^^^^^^^^^^^^^^
  File "C:\Users\igorv\AppData\Roaming\uv\python\cpython-3.13.2-windows-x86_64-none\Lib\socket.py", line 977, in getaddrinfo
    for res in _socket.getaddrinfo(host, port, family, type, proto, flags):
               ~~~~~~~~~~~~~~~~~~~^^^^^^^^^^^^^^^^^^^^^^^^^^^^^^^^^^^^^^^^
socket.gaierror: [Errno 11001] getaddrinfo failed

The above exception was the direct cause of the following exception:

Traceback (most recent call last):
  File "D:\GitHub\personal\cybersecurity-ai-assistant\.venv\Lib\site-packages\elastic_transport\_node\_http_urllib3.py", line 167, in perform_request
    response = self.pool.urlopen(
        method,
    ...<4 lines>...
        **kw,  # type: ignore[arg-type]
    )
  File "D:\GitHub\personal\cybersecurity-ai-assistant\.venv\Lib\site-packages\urllib3\connectionpool.py", line 841, in urlopen
    retries = retries.increment(
        method, url, error=new_e, _pool=self, _stacktrace=sys.exc_info()[2]
    )
  File "D:\GitHub\personal\cybersecurity-ai-assistant\.venv\Lib\site-packages\urllib3\util\retry.py", line 449, in increment
    raise reraise(type(error), error, _stacktrace)
          ~~~~~~~^^^^^^^^^^^^^^^^^^^^^^^^^^^^^^^^^
  File "D:\GitHub\personal\cybersecurity-ai-assistant\.venv\Lib\site-packages\urllib3\util\util.py", line 39, in reraise
    raise value
  File "D:\GitHub\personal\cybersecurity-ai-assistant\.venv\Lib\site-packages\urllib3\connectionpool.py", line 787, in urlopen
    response = self._make_request(
        conn,
    ...<10 lines>...
        **response_kw,
    )
  File "D:\GitHub\personal\cybersecurity-ai-assistant\.venv\Lib\site-packages\urllib3\connectionpool.py", line 493, in _make_request
    conn.request(
    ~~~~~~~~~~~~^
        method,
        ^^^^^^^
    ...<6 lines>...
        enforce_content_length=enforce_content_length,
        ^^^^^^^^^^^^^^^^^^^^^^^^^^^^^^^^^^^^^^^^^^^^^^
    )
    ^
  File "D:\GitHub\personal\cybersecurity-ai-assistant\.venv\Lib\site-packages\urllib3\connection.py", line 445, in request
    self.endheaders()
    ~~~~~~~~~~~~~~~^^
  File "C:\Users\igorv\AppData\Roaming\uv\python\cpython-3.13.2-windows-x86_64-none\Lib\http\client.py", line 1333, in endheaders
    self._send_output(message_body, encode_chunked=encode_chunked)
    ~~~~~~~~~~~~~~~~~^^^^^^^^^^^^^^^^^^^^^^^^^^^^^^^^^^^^^^^^^^^^^
  File "C:\Users\igorv\AppData\Roaming\uv\python\cpython-3.13.2-windows-x86_64-none\Lib\http\client.py", line 1093, in _send_output
    self.send(msg)
    ~~~~~~~~~^^^^^
  File "C:\Users\igorv\AppData\Roaming\uv\python\cpython-3.13.2-windows-x86_64-none\Lib\http\client.py", line 1037, in send
    self.connect()
    ~~~~~~~~~~~~^^
  File "D:\GitHub\personal\cybersecurity-ai-assistant\.venv\Lib\site-packages\urllib3\connection.py", line 276, in connect
    self.sock = self._new_conn()
                ~~~~~~~~~~~~~~^^
  File "D:\GitHub\personal\cybersecurity-ai-assistant\.venv\Lib\site-packages\urllib3\connection.py", line 205, in _new_conn
    raise NameResolutionError(self.host, self, e) from e
urllib3.exceptions.NameResolutionError: <urllib3.connection.HTTPConnection object at 0x000001CF12A40550>: Failed to resolve 'localhosthttps://b2e7e5b202d84e938f7e48f40dd02ef2.us-central1.gcp.cloud.es.io:443' ([Errno 11001] getaddrinfo failed)

The above exception was the direct cause of the following exception:

Traceback (most recent call last):
  File "D:\GitHub\personal\cybersecurity-ai-assistant\.venv\Lib\site-packages\elastic_transport\_transport.py", line 342, in perform_request
    resp = node.perform_request(
        method,
    ...<3 lines>...
        request_timeout=request_timeout,
    )
  File "D:\GitHub\personal\cybersecurity-ai-assistant\.venv\Lib\site-packages\elastic_transport\_node\_http_urllib3.py", line 202, in perform_request
    raise err from e
elastic_transport.ConnectionError: Connection error caused by: NameResolutionError(<urllib3.connection.HTTPConnection object at 0x000001CF12A40550>: Failed to resolve 'localhosthttps://b2e7e5b202d84e938f7e48f40dd02ef2.us-central1.gcp.cloud.es.io:443' ([Errno 11001] getaddrinfo failed))
2025-03-01 09:09:59,246 - elastic_transport.transport - INFO - POST http://[localhosthttps://b2e7e5b202d84e938f7e48f40dd02ef2.us-central1.gcp.cloud.es.io:443]:9200/ssh-honeypot/_doc [status:N/A duration:0.000s]
2025-03-01 09:09:59,246 - elastic_transport.node_pool - WARNING - Node <Urllib3HttpNode(http://[localhosthttps://b2e7e5b202d84e938f7e48f40dd02ef2.us-central1.gcp.cloud.es.io:443]:9200)> has failed for 4 times in a row, putting on 8 second timeout
2025-03-01 09:09:59,246 - ssh-honeypot - ERROR - Failed to send log to Elasticsearch: Connection error caused by: ConnectionError(Connection error caused by: NameResolutionError(<urllib3.connection.HTTPConnection object at 0x000001CF12A04440>: Failed to resolve 'localhosthttps://b2e7e5b202d84e938f7e48f40dd02ef2.us-central1.gcp.cloud.es.io:443' ([Errno 11001] getaddrinfo failed)))
2025-03-01 09:09:59,284 - paramiko.transport - INFO - Connected (version 2.0, client OpenSSH_for_Windows_9.5)
2025-03-01 09:09:59,292 - paramiko.transport - INFO - Auth rejected (none).
2025-03-01 09:10:00,720 - ssh-honeypot - INFO - Authentication attempt: 127.0.0.1 - username:test
2025-03-01 09:10:00,721 - elastic_transport.transport - INFO - POST http://[localhosthttps://b2e7e5b202d84e938f7e48f40dd02ef2.us-central1.gcp.cloud.es.io:443]:9200/ssh-honeypot/_doc [status:N/A duration:0.000s]
2025-03-01 09:10:00,721 - elastic_transport.node_pool - WARNING - Node <Urllib3HttpNode(http://[localhosthttps://b2e7e5b202d84e938f7e48f40dd02ef2.us-central1.gcp.cloud.es.io:443]:9200)> has failed for 1 times in a row, putting on 1 second timeout
2025-03-01 09:10:00,721 - elastic_transport.transport - WARNING - Retrying request after failure (attempt 0 of 3)
Traceback (most recent call last):
  File "D:\GitHub\personal\cybersecurity-ai-assistant\.venv\Lib\site-packages\urllib3\connection.py", line 198, in _new_conn
    sock = connection.create_connection(
        (self._dns_host, self.port),
    ...<2 lines>...
        socket_options=self.socket_options,
    )
  File "D:\GitHub\personal\cybersecurity-ai-assistant\.venv\Lib\site-packages\urllib3\util\connection.py", line 60, in create_connection
    for res in socket.getaddrinfo(host, port, family, socket.SOCK_STREAM):
               ~~~~~~~~~~~~~~~~~~^^^^^^^^^^^^^^^^^^^^^^^^^^^^^^^^^^^^^^^^
  File "C:\Users\igorv\AppData\Roaming\uv\python\cpython-3.13.2-windows-x86_64-none\Lib\socket.py", line 977, in getaddrinfo
    for res in _socket.getaddrinfo(host, port, family, type, proto, flags):
               ~~~~~~~~~~~~~~~~~~~^^^^^^^^^^^^^^^^^^^^^^^^^^^^^^^^^^^^^^^^
socket.gaierror: [Errno 11001] getaddrinfo failed

The above exception was the direct cause of the following exception:

Traceback (most recent call last):
  File "D:\GitHub\personal\cybersecurity-ai-assistant\.venv\Lib\site-packages\elastic_transport\_node\_http_urllib3.py", line 167, in perform_request
    response = self.pool.urlopen(
        method,
    ...<4 lines>...
        **kw,  # type: ignore[arg-type]
    )
  File "D:\GitHub\personal\cybersecurity-ai-assistant\.venv\Lib\site-packages\urllib3\connectionpool.py", line 841, in urlopen
    retries = retries.increment(
        method, url, error=new_e, _pool=self, _stacktrace=sys.exc_info()[2]
    )
  File "D:\GitHub\personal\cybersecurity-ai-assistant\.venv\Lib\site-packages\urllib3\util\retry.py", line 449, in increment
    raise reraise(type(error), error, _stacktrace)
          ~~~~~~~^^^^^^^^^^^^^^^^^^^^^^^^^^^^^^^^^
  File "D:\GitHub\personal\cybersecurity-ai-assistant\.venv\Lib\site-packages\urllib3\util\util.py", line 39, in reraise
    raise value
  File "D:\GitHub\personal\cybersecurity-ai-assistant\.venv\Lib\site-packages\urllib3\connectionpool.py", line 787, in urlopen
    response = self._make_request(
        conn,
    ...<10 lines>...
        **response_kw,
    )
  File "D:\GitHub\personal\cybersecurity-ai-assistant\.venv\Lib\site-packages\urllib3\connectionpool.py", line 493, in _make_request
    conn.request(
    ~~~~~~~~~~~~^
        method,
        ^^^^^^^
    ...<6 lines>...
        enforce_content_length=enforce_content_length,
        ^^^^^^^^^^^^^^^^^^^^^^^^^^^^^^^^^^^^^^^^^^^^^^
    )
    ^
  File "D:\GitHub\personal\cybersecurity-ai-assistant\.venv\Lib\site-packages\urllib3\connection.py", line 445, in request
    self.endheaders()
    ~~~~~~~~~~~~~~~^^
  File "C:\Users\igorv\AppData\Roaming\uv\python\cpython-3.13.2-windows-x86_64-none\Lib\http\client.py", line 1333, in endheaders
    self._send_output(message_body, encode_chunked=encode_chunked)
    ~~~~~~~~~~~~~~~~~^^^^^^^^^^^^^^^^^^^^^^^^^^^^^^^^^^^^^^^^^^^^^
  File "C:\Users\igorv\AppData\Roaming\uv\python\cpython-3.13.2-windows-x86_64-none\Lib\http\client.py", line 1093, in _send_output
    self.send(msg)
    ~~~~~~~~~^^^^^
  File "C:\Users\igorv\AppData\Roaming\uv\python\cpython-3.13.2-windows-x86_64-none\Lib\http\client.py", line 1037, in send
    self.connect()
    ~~~~~~~~~~~~^^
  File "D:\GitHub\personal\cybersecurity-ai-assistant\.venv\Lib\site-packages\urllib3\connection.py", line 276, in connect
    self.sock = self._new_conn()
                ~~~~~~~~~~~~~~^^
  File "D:\GitHub\personal\cybersecurity-ai-assistant\.venv\Lib\site-packages\urllib3\connection.py", line 205, in _new_conn
    raise NameResolutionError(self.host, self, e) from e
urllib3.exceptions.NameResolutionError: <urllib3.connection.HTTPConnection object at 0x000001CF12AD0050>: Failed to resolve 'localhosthttps://b2e7e5b202d84e938f7e48f40dd02ef2.us-central1.gcp.cloud.es.io:443' ([Errno 11001] getaddrinfo failed)

The above exception was the direct cause of the following exception:

Traceback (most recent call last):
  File "D:\GitHub\personal\cybersecurity-ai-assistant\.venv\Lib\site-packages\elastic_transport\_transport.py", line 342, in perform_request
    resp = node.perform_request(
        method,
    ...<3 lines>...
        request_timeout=request_timeout,
    )
  File "D:\GitHub\personal\cybersecurity-ai-assistant\.venv\Lib\site-packages\elastic_transport\_node\_http_urllib3.py", line 202, in perform_request
    raise err from e
elastic_transport.ConnectionError: Connection error caused by: NameResolutionError(<urllib3.connection.HTTPConnection object at 0x000001CF12AD0050>: Failed to resolve 'localhosthttps://b2e7e5b202d84e938f7e48f40dd02ef2.us-central1.gcp.cloud.es.io:443' ([Errno 11001] getaddrinfo failed))
2025-03-01 09:10:00,725 - elastic_transport.transport - INFO - POST http://[localhosthttps://b2e7e5b202d84e938f7e48f40dd02ef2.us-central1.gcp.cloud.es.io:443]:9200/ssh-honeypot/_doc [status:N/A duration:0.000s]
2025-03-01 09:10:00,725 - elastic_transport.node_pool - WARNING - Node <Urllib3HttpNode(http://[localhosthttps://b2e7e5b202d84e938f7e48f40dd02ef2.us-central1.gcp.cloud.es.io:443]:9200)> has failed for 2 times in a row, putting on 2 second timeout
2025-03-01 09:10:00,725 - elastic_transport.transport - WARNING - Retrying request after failure (attempt 1 of 3)
Traceback (most recent call last):
  File "D:\GitHub\personal\cybersecurity-ai-assistant\.venv\Lib\site-packages\urllib3\connection.py", line 198, in _new_conn
    sock = connection.create_connection(
        (self._dns_host, self.port),
    ...<2 lines>...
        socket_options=self.socket_options,
    )
  File "D:\GitHub\personal\cybersecurity-ai-assistant\.venv\Lib\site-packages\urllib3\util\connection.py", line 60, in create_connection
    for res in socket.getaddrinfo(host, port, family, socket.SOCK_STREAM):
               ~~~~~~~~~~~~~~~~~~^^^^^^^^^^^^^^^^^^^^^^^^^^^^^^^^^^^^^^^^
  File "C:\Users\igorv\AppData\Roaming\uv\python\cpython-3.13.2-windows-x86_64-none\Lib\socket.py", line 977, in getaddrinfo
    for res in _socket.getaddrinfo(host, port, family, type, proto, flags):
               ~~~~~~~~~~~~~~~~~~~^^^^^^^^^^^^^^^^^^^^^^^^^^^^^^^^^^^^^^^^
socket.gaierror: [Errno 11001] getaddrinfo failed

The above exception was the direct cause of the following exception:

Traceback (most recent call last):
  File "D:\GitHub\personal\cybersecurity-ai-assistant\.venv\Lib\site-packages\elastic_transport\_node\_http_urllib3.py", line 167, in perform_request
    response = self.pool.urlopen(
        method,
    ...<4 lines>...
        **kw,  # type: ignore[arg-type]
    )
  File "D:\GitHub\personal\cybersecurity-ai-assistant\.venv\Lib\site-packages\urllib3\connectionpool.py", line 841, in urlopen
    retries = retries.increment(
        method, url, error=new_e, _pool=self, _stacktrace=sys.exc_info()[2]
    )
  File "D:\GitHub\personal\cybersecurity-ai-assistant\.venv\Lib\site-packages\urllib3\util\retry.py", line 449, in increment
    raise reraise(type(error), error, _stacktrace)
          ~~~~~~~^^^^^^^^^^^^^^^^^^^^^^^^^^^^^^^^^
  File "D:\GitHub\personal\cybersecurity-ai-assistant\.venv\Lib\site-packages\urllib3\util\util.py", line 39, in reraise
    raise value
  File "D:\GitHub\personal\cybersecurity-ai-assistant\.venv\Lib\site-packages\urllib3\connectionpool.py", line 787, in urlopen
    response = self._make_request(
        conn,
    ...<10 lines>...
        **response_kw,
    )
  File "D:\GitHub\personal\cybersecurity-ai-assistant\.venv\Lib\site-packages\urllib3\connectionpool.py", line 493, in _make_request
    conn.request(
    ~~~~~~~~~~~~^
        method,
        ^^^^^^^
    ...<6 lines>...
        enforce_content_length=enforce_content_length,
        ^^^^^^^^^^^^^^^^^^^^^^^^^^^^^^^^^^^^^^^^^^^^^^
    )
    ^
  File "D:\GitHub\personal\cybersecurity-ai-assistant\.venv\Lib\site-packages\urllib3\connection.py", line 445, in request
    self.endheaders()
    ~~~~~~~~~~~~~~~^^
  File "C:\Users\igorv\AppData\Roaming\uv\python\cpython-3.13.2-windows-x86_64-none\Lib\http\client.py", line 1333, in endheaders
    self._send_output(message_body, encode_chunked=encode_chunked)
    ~~~~~~~~~~~~~~~~~^^^^^^^^^^^^^^^^^^^^^^^^^^^^^^^^^^^^^^^^^^^^^
  File "C:\Users\igorv\AppData\Roaming\uv\python\cpython-3.13.2-windows-x86_64-none\Lib\http\client.py", line 1093, in _send_output
    self.send(msg)
    ~~~~~~~~~^^^^^
  File "C:\Users\igorv\AppData\Roaming\uv\python\cpython-3.13.2-windows-x86_64-none\Lib\http\client.py", line 1037, in send
    self.connect()
    ~~~~~~~~~~~~^^
  File "D:\GitHub\personal\cybersecurity-ai-assistant\.venv\Lib\site-packages\urllib3\connection.py", line 276, in connect
    self.sock = self._new_conn()
                ~~~~~~~~~~~~~~^^
  File "D:\GitHub\personal\cybersecurity-ai-assistant\.venv\Lib\site-packages\urllib3\connection.py", line 205, in _new_conn
    raise NameResolutionError(self.host, self, e) from e
urllib3.exceptions.NameResolutionError: <urllib3.connection.HTTPConnection object at 0x000001CF12A08B90>: Failed to resolve 'localhosthttps://b2e7e5b202d84e938f7e48f40dd02ef2.us-central1.gcp.cloud.es.io:443' ([Errno 11001] getaddrinfo failed)

The above exception was the direct cause of the following exception:

Traceback (most recent call last):
  File "D:\GitHub\personal\cybersecurity-ai-assistant\.venv\Lib\site-packages\elastic_transport\_transport.py", line 342, in perform_request
    resp = node.perform_request(
        method,
    ...<3 lines>...
        request_timeout=request_timeout,
    )
  File "D:\GitHub\personal\cybersecurity-ai-assistant\.venv\Lib\site-packages\elastic_transport\_node\_http_urllib3.py", line 202, in perform_request
    raise err from e
elastic_transport.ConnectionError: Connection error caused by: NameResolutionError(<urllib3.connection.HTTPConnection object at 0x000001CF12A08B90>: Failed to resolve 'localhosthttps://b2e7e5b202d84e938f7e48f40dd02ef2.us-central1.gcp.cloud.es.io:443' ([Errno 11001] getaddrinfo failed))
2025-03-01 09:10:00,728 - elastic_transport.transport - INFO - POST http://[localhosthttps://b2e7e5b202d84e938f7e48f40dd02ef2.us-central1.gcp.cloud.es.io:443]:9200/ssh-honeypot/_doc [status:N/A duration:0.000s]
2025-03-01 09:10:00,729 - elastic_transport.node_pool - WARNING - Node <Urllib3HttpNode(http://[localhosthttps://b2e7e5b202d84e938f7e48f40dd02ef2.us-central1.gcp.cloud.es.io:443]:9200)> has failed for 3 times in a row, putting on 4 second timeout
2025-03-01 09:10:00,729 - elastic_transport.transport - WARNING - Retrying request after failure (attempt 2 of 3)
Traceback (most recent call last):
  File "D:\GitHub\personal\cybersecurity-ai-assistant\.venv\Lib\site-packages\urllib3\connection.py", line 198, in _new_conn
    sock = connection.create_connection(
        (self._dns_host, self.port),
    ...<2 lines>...
        socket_options=self.socket_options,
    )
  File "D:\GitHub\personal\cybersecurity-ai-assistant\.venv\Lib\site-packages\urllib3\util\connection.py", line 60, in create_connection
    for res in socket.getaddrinfo(host, port, family, socket.SOCK_STREAM):
               ~~~~~~~~~~~~~~~~~~^^^^^^^^^^^^^^^^^^^^^^^^^^^^^^^^^^^^^^^^
  File "C:\Users\igorv\AppData\Roaming\uv\python\cpython-3.13.2-windows-x86_64-none\Lib\socket.py", line 977, in getaddrinfo
    for res in _socket.getaddrinfo(host, port, family, type, proto, flags):
               ~~~~~~~~~~~~~~~~~~~^^^^^^^^^^^^^^^^^^^^^^^^^^^^^^^^^^^^^^^^
socket.gaierror: [Errno 11001] getaddrinfo failed

The above exception was the direct cause of the following exception:

Traceback (most recent call last):
  File "D:\GitHub\personal\cybersecurity-ai-assistant\.venv\Lib\site-packages\elastic_transport\_node\_http_urllib3.py", line 167, in perform_request
    response = self.pool.urlopen(
        method,
    ...<4 lines>...
        **kw,  # type: ignore[arg-type]
    )
  File "D:\GitHub\personal\cybersecurity-ai-assistant\.venv\Lib\site-packages\urllib3\connectionpool.py", line 841, in urlopen
    retries = retries.increment(
        method, url, error=new_e, _pool=self, _stacktrace=sys.exc_info()[2]
    )
  File "D:\GitHub\personal\cybersecurity-ai-assistant\.venv\Lib\site-packages\urllib3\util\retry.py", line 449, in increment
    raise reraise(type(error), error, _stacktrace)
          ~~~~~~~^^^^^^^^^^^^^^^^^^^^^^^^^^^^^^^^^
  File "D:\GitHub\personal\cybersecurity-ai-assistant\.venv\Lib\site-packages\urllib3\util\util.py", line 39, in reraise
    raise value
  File "D:\GitHub\personal\cybersecurity-ai-assistant\.venv\Lib\site-packages\urllib3\connectionpool.py", line 787, in urlopen
    response = self._make_request(
        conn,
    ...<10 lines>...
        **response_kw,
    )
  File "D:\GitHub\personal\cybersecurity-ai-assistant\.venv\Lib\site-packages\urllib3\connectionpool.py", line 493, in _make_request
    conn.request(
    ~~~~~~~~~~~~^
        method,
        ^^^^^^^
    ...<6 lines>...
        enforce_content_length=enforce_content_length,
        ^^^^^^^^^^^^^^^^^^^^^^^^^^^^^^^^^^^^^^^^^^^^^^
    )
    ^
  File "D:\GitHub\personal\cybersecurity-ai-assistant\.venv\Lib\site-packages\urllib3\connection.py", line 445, in request
    self.endheaders()
    ~~~~~~~~~~~~~~~^^
  File "C:\Users\igorv\AppData\Roaming\uv\python\cpython-3.13.2-windows-x86_64-none\Lib\http\client.py", line 1333, in endheaders
    self._send_output(message_body, encode_chunked=encode_chunked)
    ~~~~~~~~~~~~~~~~~^^^^^^^^^^^^^^^^^^^^^^^^^^^^^^^^^^^^^^^^^^^^^
  File "C:\Users\igorv\AppData\Roaming\uv\python\cpython-3.13.2-windows-x86_64-none\Lib\http\client.py", line 1093, in _send_output
    self.send(msg)
    ~~~~~~~~~^^^^^
  File "C:\Users\igorv\AppData\Roaming\uv\python\cpython-3.13.2-windows-x86_64-none\Lib\http\client.py", line 1037, in send
    self.connect()
    ~~~~~~~~~~~~^^
  File "D:\GitHub\personal\cybersecurity-ai-assistant\.venv\Lib\site-packages\urllib3\connection.py", line 276, in connect
    self.sock = self._new_conn()
                ~~~~~~~~~~~~~~^^
  File "D:\GitHub\personal\cybersecurity-ai-assistant\.venv\Lib\site-packages\urllib3\connection.py", line 205, in _new_conn
    raise NameResolutionError(self.host, self, e) from e
urllib3.exceptions.NameResolutionError: <urllib3.connection.HTTPConnection object at 0x000001CF12975D00>: Failed to resolve 'localhosthttps://b2e7e5b202d84e938f7e48f40dd02ef2.us-central1.gcp.cloud.es.io:443' ([Errno 11001] getaddrinfo failed)

The above exception was the direct cause of the following exception:

Traceback (most recent call last):
  File "D:\GitHub\personal\cybersecurity-ai-assistant\.venv\Lib\site-packages\elastic_transport\_transport.py", line 342, in perform_request
    resp = node.perform_request(
        method,
    ...<3 lines>...
        request_timeout=request_timeout,
    )
  File "D:\GitHub\personal\cybersecurity-ai-assistant\.venv\Lib\site-packages\elastic_transport\_node\_http_urllib3.py", line 202, in perform_request
    raise err from e
elastic_transport.ConnectionError: Connection error caused by: NameResolutionError(<urllib3.connection.HTTPConnection object at 0x000001CF12975D00>: Failed to resolve 'localhosthttps://b2e7e5b202d84e938f7e48f40dd02ef2.us-central1.gcp.cloud.es.io:443' ([Errno 11001] getaddrinfo failed))
2025-03-01 09:10:00,735 - elastic_transport.transport - INFO - POST http://[localhosthttps://b2e7e5b202d84e938f7e48f40dd02ef2.us-central1.gcp.cloud.es.io:443]:9200/ssh-honeypot/_doc [status:N/A duration:0.000s]
2025-03-01 09:10:00,735 - elastic_transport.node_pool - WARNING - Node <Urllib3HttpNode(http://[localhosthttps://b2e7e5b202d84e938f7e48f40dd02ef2.us-central1.gcp.cloud.es.io:443]:9200)> has failed for 4 times in a row, putting on 8 second timeout
2025-03-01 09:10:00,735 - ssh-honeypot - ERROR - Failed to send log to Elasticsearch: Connection error caused by: ConnectionError(Connection error caused by: NameResolutionError(<urllib3.connection.HTTPConnection object at 0x000001CF12AD0050>: Failed to resolve 'localhosthttps://b2e7e5b202d84e938f7e48f40dd02ef2.us-central1.gcp.cloud.es.io:443' ([Errno 11001] getaddrinfo failed)))
2025-03-01 09:10:00,735 - paramiko.transport - INFO - Auth rejected (password).
2025-03-01 09:10:03,873 - ssh-honeypot - INFO - Authentication attempt: 127.0.0.1 - username:root
2025-03-01 09:10:03,874 - elastic_transport.transport - INFO - POST http://[localhosthttps://b2e7e5b202d84e938f7e48f40dd02ef2.us-central1.gcp.cloud.es.io:443]:9200/ssh-honeypot/_doc [status:N/A duration:0.000s]
2025-03-01 09:10:03,874 - elastic_transport.node_pool - WARNING - Node <Urllib3HttpNode(http://[localhosthttps://b2e7e5b202d84e938f7e48f40dd02ef2.us-central1.gcp.cloud.es.io:443]:9200)> has failed for 1 times in a row, putting on 1 second timeout
2025-03-01 09:10:03,874 - elastic_transport.transport - WARNING - Retrying request after failure (attempt 0 of 3)
Traceback (most recent call last):
  File "D:\GitHub\personal\cybersecurity-ai-assistant\.venv\Lib\site-packages\urllib3\connection.py", line 198, in _new_conn
    sock = connection.create_connection(
        (self._dns_host, self.port),
    ...<2 lines>...
        socket_options=self.socket_options,
    )
  File "D:\GitHub\personal\cybersecurity-ai-assistant\.venv\Lib\site-packages\urllib3\util\connection.py", line 60, in create_connection
    for res in socket.getaddrinfo(host, port, family, socket.SOCK_STREAM):
               ~~~~~~~~~~~~~~~~~~^^^^^^^^^^^^^^^^^^^^^^^^^^^^^^^^^^^^^^^^
  File "C:\Users\igorv\AppData\Roaming\uv\python\cpython-3.13.2-windows-x86_64-none\Lib\socket.py", line 977, in getaddrinfo
    for res in _socket.getaddrinfo(host, port, family, type, proto, flags):
               ~~~~~~~~~~~~~~~~~~~^^^^^^^^^^^^^^^^^^^^^^^^^^^^^^^^^^^^^^^^
socket.gaierror: [Errno 11001] getaddrinfo failed

The above exception was the direct cause of the following exception:

Traceback (most recent call last):
  File "D:\GitHub\personal\cybersecurity-ai-assistant\.venv\Lib\site-packages\elastic_transport\_node\_http_urllib3.py", line 167, in perform_request
    response = self.pool.urlopen(
        method,
    ...<4 lines>...
        **kw,  # type: ignore[arg-type]
    )
  File "D:\GitHub\personal\cybersecurity-ai-assistant\.venv\Lib\site-packages\urllib3\connectionpool.py", line 841, in urlopen
    retries = retries.increment(
        method, url, error=new_e, _pool=self, _stacktrace=sys.exc_info()[2]
    )
  File "D:\GitHub\personal\cybersecurity-ai-assistant\.venv\Lib\site-packages\urllib3\util\retry.py", line 449, in increment
    raise reraise(type(error), error, _stacktrace)
          ~~~~~~~^^^^^^^^^^^^^^^^^^^^^^^^^^^^^^^^^
  File "D:\GitHub\personal\cybersecurity-ai-assistant\.venv\Lib\site-packages\urllib3\util\util.py", line 39, in reraise
    raise value
  File "D:\GitHub\personal\cybersecurity-ai-assistant\.venv\Lib\site-packages\urllib3\connectionpool.py", line 787, in urlopen
    response = self._make_request(
        conn,
    ...<10 lines>...
        **response_kw,
    )
  File "D:\GitHub\personal\cybersecurity-ai-assistant\.venv\Lib\site-packages\urllib3\connectionpool.py", line 493, in _make_request
    conn.request(
    ~~~~~~~~~~~~^
        method,
        ^^^^^^^
    ...<6 lines>...
        enforce_content_length=enforce_content_length,
        ^^^^^^^^^^^^^^^^^^^^^^^^^^^^^^^^^^^^^^^^^^^^^^
    )
    ^
  File "D:\GitHub\personal\cybersecurity-ai-assistant\.venv\Lib\site-packages\urllib3\connection.py", line 445, in request
    self.endheaders()
    ~~~~~~~~~~~~~~~^^
  File "C:\Users\igorv\AppData\Roaming\uv\python\cpython-3.13.2-windows-x86_64-none\Lib\http\client.py", line 1333, in endheaders
    self._send_output(message_body, encode_chunked=encode_chunked)
    ~~~~~~~~~~~~~~~~~^^^^^^^^^^^^^^^^^^^^^^^^^^^^^^^^^^^^^^^^^^^^^
  File "C:\Users\igorv\AppData\Roaming\uv\python\cpython-3.13.2-windows-x86_64-none\Lib\http\client.py", line 1093, in _send_output
    self.send(msg)
    ~~~~~~~~~^^^^^
  File "C:\Users\igorv\AppData\Roaming\uv\python\cpython-3.13.2-windows-x86_64-none\Lib\http\client.py", line 1037, in send
    self.connect()
    ~~~~~~~~~~~~^^
  File "D:\GitHub\personal\cybersecurity-ai-assistant\.venv\Lib\site-packages\urllib3\connection.py", line 276, in connect
    self.sock = self._new_conn()
                ~~~~~~~~~~~~~~^^
  File "D:\GitHub\personal\cybersecurity-ai-assistant\.venv\Lib\site-packages\urllib3\connection.py", line 205, in _new_conn
    raise NameResolutionError(self.host, self, e) from e
urllib3.exceptions.NameResolutionError: <urllib3.connection.HTTPConnection object at 0x000001CF12975260>: Failed to resolve 'localhosthttps://b2e7e5b202d84e938f7e48f40dd02ef2.us-central1.gcp.cloud.es.io:443' ([Errno 11001] getaddrinfo failed)

The above exception was the direct cause of the following exception:

Traceback (most recent call last):
  File "D:\GitHub\personal\cybersecurity-ai-assistant\.venv\Lib\site-packages\elastic_transport\_transport.py", line 342, in perform_request
    resp = node.perform_request(
        method,
    ...<3 lines>...
        request_timeout=request_timeout,
    )
  File "D:\GitHub\personal\cybersecurity-ai-assistant\.venv\Lib\site-packages\elastic_transport\_node\_http_urllib3.py", line 202, in perform_request
    raise err from e
elastic_transport.ConnectionError: Connection error caused by: NameResolutionError(<urllib3.connection.HTTPConnection object at 0x000001CF12975260>: Failed to resolve 'localhosthttps://b2e7e5b202d84e938f7e48f40dd02ef2.us-central1.gcp.cloud.es.io:443' ([Errno 11001] getaddrinfo failed))
2025-03-01 09:10:03,877 - elastic_transport.transport - INFO - POST http://[localhosthttps://b2e7e5b202d84e938f7e48f40dd02ef2.us-central1.gcp.cloud.es.io:443]:9200/ssh-honeypot/_doc [status:N/A duration:0.000s]
2025-03-01 09:10:03,877 - elastic_transport.node_pool - WARNING - Node <Urllib3HttpNode(http://[localhosthttps://b2e7e5b202d84e938f7e48f40dd02ef2.us-central1.gcp.cloud.es.io:443]:9200)> has failed for 2 times in a row, putting on 2 second timeout
2025-03-01 09:10:03,878 - elastic_transport.transport - WARNING - Retrying request after failure (attempt 1 of 3)
Traceback (most recent call last):
  File "D:\GitHub\personal\cybersecurity-ai-assistant\.venv\Lib\site-packages\urllib3\connection.py", line 198, in _new_conn
    sock = connection.create_connection(
        (self._dns_host, self.port),
    ...<2 lines>...
        socket_options=self.socket_options,
    )
  File "D:\GitHub\personal\cybersecurity-ai-assistant\.venv\Lib\site-packages\urllib3\util\connection.py", line 60, in create_connection
    for res in socket.getaddrinfo(host, port, family, socket.SOCK_STREAM):
               ~~~~~~~~~~~~~~~~~~^^^^^^^^^^^^^^^^^^^^^^^^^^^^^^^^^^^^^^^^
  File "C:\Users\igorv\AppData\Roaming\uv\python\cpython-3.13.2-windows-x86_64-none\Lib\socket.py", line 977, in getaddrinfo
    for res in _socket.getaddrinfo(host, port, family, type, proto, flags):
               ~~~~~~~~~~~~~~~~~~~^^^^^^^^^^^^^^^^^^^^^^^^^^^^^^^^^^^^^^^^
socket.gaierror: [Errno 11001] getaddrinfo failed

The above exception was the direct cause of the following exception:

Traceback (most recent call last):
  File "D:\GitHub\personal\cybersecurity-ai-assistant\.venv\Lib\site-packages\elastic_transport\_node\_http_urllib3.py", line 167, in perform_request
    response = self.pool.urlopen(
        method,
    ...<4 lines>...
        **kw,  # type: ignore[arg-type]
    )
  File "D:\GitHub\personal\cybersecurity-ai-assistant\.venv\Lib\site-packages\urllib3\connectionpool.py", line 841, in urlopen
    retries = retries.increment(
        method, url, error=new_e, _pool=self, _stacktrace=sys.exc_info()[2]
    )
  File "D:\GitHub\personal\cybersecurity-ai-assistant\.venv\Lib\site-packages\urllib3\util\retry.py", line 449, in increment
    raise reraise(type(error), error, _stacktrace)
          ~~~~~~~^^^^^^^^^^^^^^^^^^^^^^^^^^^^^^^^^
  File "D:\GitHub\personal\cybersecurity-ai-assistant\.venv\Lib\site-packages\urllib3\util\util.py", line 39, in reraise
    raise value
  File "D:\GitHub\personal\cybersecurity-ai-assistant\.venv\Lib\site-packages\urllib3\connectionpool.py", line 787, in urlopen
    response = self._make_request(
        conn,
    ...<10 lines>...
        **response_kw,
    )
  File "D:\GitHub\personal\cybersecurity-ai-assistant\.venv\Lib\site-packages\urllib3\connectionpool.py", line 493, in _make_request
    conn.request(
    ~~~~~~~~~~~~^
        method,
        ^^^^^^^
    ...<6 lines>...
        enforce_content_length=enforce_content_length,
        ^^^^^^^^^^^^^^^^^^^^^^^^^^^^^^^^^^^^^^^^^^^^^^
    )
    ^
  File "D:\GitHub\personal\cybersecurity-ai-assistant\.venv\Lib\site-packages\urllib3\connection.py", line 445, in request
    self.endheaders()
    ~~~~~~~~~~~~~~~^^
  File "C:\Users\igorv\AppData\Roaming\uv\python\cpython-3.13.2-windows-x86_64-none\Lib\http\client.py", line 1333, in endheaders
    self._send_output(message_body, encode_chunked=encode_chunked)
    ~~~~~~~~~~~~~~~~~^^^^^^^^^^^^^^^^^^^^^^^^^^^^^^^^^^^^^^^^^^^^^
  File "C:\Users\igorv\AppData\Roaming\uv\python\cpython-3.13.2-windows-x86_64-none\Lib\http\client.py", line 1093, in _send_output
    self.send(msg)
    ~~~~~~~~~^^^^^
  File "C:\Users\igorv\AppData\Roaming\uv\python\cpython-3.13.2-windows-x86_64-none\Lib\http\client.py", line 1037, in send
    self.connect()
    ~~~~~~~~~~~~^^
  File "D:\GitHub\personal\cybersecurity-ai-assistant\.venv\Lib\site-packages\urllib3\connection.py", line 276, in connect
    self.sock = self._new_conn()
                ~~~~~~~~~~~~~~^^
  File "D:\GitHub\personal\cybersecurity-ai-assistant\.venv\Lib\site-packages\urllib3\connection.py", line 205, in _new_conn
    raise NameResolutionError(self.host, self, e) from e
urllib3.exceptions.NameResolutionError: <urllib3.connection.HTTPConnection object at 0x000001CF12974E20>: Failed to resolve 'localhosthttps://b2e7e5b202d84e938f7e48f40dd02ef2.us-central1.gcp.cloud.es.io:443' ([Errno 11001] getaddrinfo failed)

The above exception was the direct cause of the following exception:

Traceback (most recent call last):
  File "D:\GitHub\personal\cybersecurity-ai-assistant\.venv\Lib\site-packages\elastic_transport\_transport.py", line 342, in perform_request
    resp = node.perform_request(
        method,
    ...<3 lines>...
        request_timeout=request_timeout,
    )
  File "D:\GitHub\personal\cybersecurity-ai-assistant\.venv\Lib\site-packages\elastic_transport\_node\_http_urllib3.py", line 202, in perform_request
    raise err from e
elastic_transport.ConnectionError: Connection error caused by: NameResolutionError(<urllib3.connection.HTTPConnection object at 0x000001CF12974E20>: Failed to resolve 'localhosthttps://b2e7e5b202d84e938f7e48f40dd02ef2.us-central1.gcp.cloud.es.io:443' ([Errno 11001] getaddrinfo failed))
2025-03-01 09:10:03,881 - elastic_transport.transport - INFO - POST http://[localhosthttps://b2e7e5b202d84e938f7e48f40dd02ef2.us-central1.gcp.cloud.es.io:443]:9200/ssh-honeypot/_doc [status:N/A duration:0.000s]
2025-03-01 09:10:03,881 - elastic_transport.node_pool - WARNING - Node <Urllib3HttpNode(http://[localhosthttps://b2e7e5b202d84e938f7e48f40dd02ef2.us-central1.gcp.cloud.es.io:443]:9200)> has failed for 3 times in a row, putting on 4 second timeout
2025-03-01 09:10:03,881 - elastic_transport.transport - WARNING - Retrying request after failure (attempt 2 of 3)
Traceback (most recent call last):
  File "D:\GitHub\personal\cybersecurity-ai-assistant\.venv\Lib\site-packages\urllib3\connection.py", line 198, in _new_conn
    sock = connection.create_connection(
        (self._dns_host, self.port),
    ...<2 lines>...
        socket_options=self.socket_options,
    )
  File "D:\GitHub\personal\cybersecurity-ai-assistant\.venv\Lib\site-packages\urllib3\util\connection.py", line 60, in create_connection
    for res in socket.getaddrinfo(host, port, family, socket.SOCK_STREAM):
               ~~~~~~~~~~~~~~~~~~^^^^^^^^^^^^^^^^^^^^^^^^^^^^^^^^^^^^^^^^
  File "C:\Users\igorv\AppData\Roaming\uv\python\cpython-3.13.2-windows-x86_64-none\Lib\socket.py", line 977, in getaddrinfo
    for res in _socket.getaddrinfo(host, port, family, type, proto, flags):
               ~~~~~~~~~~~~~~~~~~~^^^^^^^^^^^^^^^^^^^^^^^^^^^^^^^^^^^^^^^^
socket.gaierror: [Errno 11001] getaddrinfo failed

The above exception was the direct cause of the following exception:

Traceback (most recent call last):
  File "D:\GitHub\personal\cybersecurity-ai-assistant\.venv\Lib\site-packages\elastic_transport\_node\_http_urllib3.py", line 167, in perform_request
    response = self.pool.urlopen(
        method,
    ...<4 lines>...
        **kw,  # type: ignore[arg-type]
    )
  File "D:\GitHub\personal\cybersecurity-ai-assistant\.venv\Lib\site-packages\urllib3\connectionpool.py", line 841, in urlopen
    retries = retries.increment(
        method, url, error=new_e, _pool=self, _stacktrace=sys.exc_info()[2]
    )
  File "D:\GitHub\personal\cybersecurity-ai-assistant\.venv\Lib\site-packages\urllib3\util\retry.py", line 449, in increment
    raise reraise(type(error), error, _stacktrace)
          ~~~~~~~^^^^^^^^^^^^^^^^^^^^^^^^^^^^^^^^^
  File "D:\GitHub\personal\cybersecurity-ai-assistant\.venv\Lib\site-packages\urllib3\util\util.py", line 39, in reraise
    raise value
  File "D:\GitHub\personal\cybersecurity-ai-assistant\.venv\Lib\site-packages\urllib3\connectionpool.py", line 787, in urlopen
    response = self._make_request(
        conn,
    ...<10 lines>...
        **response_kw,
    )
  File "D:\GitHub\personal\cybersecurity-ai-assistant\.venv\Lib\site-packages\urllib3\connectionpool.py", line 493, in _make_request
    conn.request(
    ~~~~~~~~~~~~^
        method,
        ^^^^^^^
    ...<6 lines>...
        enforce_content_length=enforce_content_length,
        ^^^^^^^^^^^^^^^^^^^^^^^^^^^^^^^^^^^^^^^^^^^^^^
    )
    ^
  File "D:\GitHub\personal\cybersecurity-ai-assistant\.venv\Lib\site-packages\urllib3\connection.py", line 445, in request
    self.endheaders()
    ~~~~~~~~~~~~~~~^^
  File "C:\Users\igorv\AppData\Roaming\uv\python\cpython-3.13.2-windows-x86_64-none\Lib\http\client.py", line 1333, in endheaders
    self._send_output(message_body, encode_chunked=encode_chunked)
    ~~~~~~~~~~~~~~~~~^^^^^^^^^^^^^^^^^^^^^^^^^^^^^^^^^^^^^^^^^^^^^
  File "C:\Users\igorv\AppData\Roaming\uv\python\cpython-3.13.2-windows-x86_64-none\Lib\http\client.py", line 1093, in _send_output
    self.send(msg)
    ~~~~~~~~~^^^^^
  File "C:\Users\igorv\AppData\Roaming\uv\python\cpython-3.13.2-windows-x86_64-none\Lib\http\client.py", line 1037, in send
    self.connect()
    ~~~~~~~~~~~~^^
  File "D:\GitHub\personal\cybersecurity-ai-assistant\.venv\Lib\site-packages\urllib3\connection.py", line 276, in connect
    self.sock = self._new_conn()
                ~~~~~~~~~~~~~~^^
  File "D:\GitHub\personal\cybersecurity-ai-assistant\.venv\Lib\site-packages\urllib3\connection.py", line 205, in _new_conn
    raise NameResolutionError(self.host, self, e) from e
urllib3.exceptions.NameResolutionError: <urllib3.connection.HTTPConnection object at 0x000001CF12975370>: Failed to resolve 'localhosthttps://b2e7e5b202d84e938f7e48f40dd02ef2.us-central1.gcp.cloud.es.io:443' ([Errno 11001] getaddrinfo failed)

The above exception was the direct cause of the following exception:

Traceback (most recent call last):
  File "D:\GitHub\personal\cybersecurity-ai-assistant\.venv\Lib\site-packages\elastic_transport\_transport.py", line 342, in perform_request
    resp = node.perform_request(
        method,
    ...<3 lines>...
        request_timeout=request_timeout,
    )
  File "D:\GitHub\personal\cybersecurity-ai-assistant\.venv\Lib\site-packages\elastic_transport\_node\_http_urllib3.py", line 202, in perform_request
    raise err from e
elastic_transport.ConnectionError: Connection error caused by: NameResolutionError(<urllib3.connection.HTTPConnection object at 0x000001CF12975370>: Failed to resolve 'localhosthttps://b2e7e5b202d84e938f7e48f40dd02ef2.us-central1.gcp.cloud.es.io:443' ([Errno 11001] getaddrinfo failed))
2025-03-01 09:10:03,884 - elastic_transport.transport - INFO - POST http://[localhosthttps://b2e7e5b202d84e938f7e48f40dd02ef2.us-central1.gcp.cloud.es.io:443]:9200/ssh-honeypot/_doc [status:N/A duration:0.000s]
2025-03-01 09:10:03,885 - elastic_transport.node_pool - WARNING - Node <Urllib3HttpNode(http://[localhosthttps://b2e7e5b202d84e938f7e48f40dd02ef2.us-central1.gcp.cloud.es.io:443]:9200)> has failed for 4 times in a row, putting on 8 second timeout
2025-03-01 09:10:03,885 - ssh-honeypot - ERROR - Failed to send log to Elasticsearch: Connection error caused by: ConnectionError(Connection error caused by: NameResolutionError(<urllib3.connection.HTTPConnection object at 0x000001CF12975260>: Failed to resolve 'localhosthttps://b2e7e5b202d84e938f7e48f40dd02ef2.us-central1.gcp.cloud.es.io:443' ([Errno 11001] getaddrinfo failed)))
2025-03-01 09:10:03,885 - paramiko.transport - INFO - Auth rejected (password).
2025-03-01 09:10:07,336 - ssh-honeypot - INFO - Authentication attempt: 127.0.0.1 - username:dadasds
2025-03-01 09:10:07,337 - elastic_transport.transport - INFO - POST http://[localhosthttps://b2e7e5b202d84e938f7e48f40dd02ef2.us-central1.gcp.cloud.es.io:443]:9200/ssh-honeypot/_doc [status:N/A duration:0.000s]
2025-03-01 09:10:07,337 - elastic_transport.node_pool - WARNING - Node <Urllib3HttpNode(http://[localhosthttps://b2e7e5b202d84e938f7e48f40dd02ef2.us-central1.gcp.cloud.es.io:443]:9200)> has failed for 1 times in a row, putting on 1 second timeout
2025-03-01 09:10:07,337 - elastic_transport.transport - WARNING - Retrying request after failure (attempt 0 of 3)
Traceback (most recent call last):
  File "D:\GitHub\personal\cybersecurity-ai-assistant\.venv\Lib\site-packages\urllib3\connection.py", line 198, in _new_conn
    sock = connection.create_connection(
        (self._dns_host, self.port),
    ...<2 lines>...
        socket_options=self.socket_options,
    )
  File "D:\GitHub\personal\cybersecurity-ai-assistant\.venv\Lib\site-packages\urllib3\util\connection.py", line 60, in create_connection
    for res in socket.getaddrinfo(host, port, family, socket.SOCK_STREAM):
               ~~~~~~~~~~~~~~~~~~^^^^^^^^^^^^^^^^^^^^^^^^^^^^^^^^^^^^^^^^
  File "C:\Users\igorv\AppData\Roaming\uv\python\cpython-3.13.2-windows-x86_64-none\Lib\socket.py", line 977, in getaddrinfo
    for res in _socket.getaddrinfo(host, port, family, type, proto, flags):
               ~~~~~~~~~~~~~~~~~~~^^^^^^^^^^^^^^^^^^^^^^^^^^^^^^^^^^^^^^^^
socket.gaierror: [Errno 11001] getaddrinfo failed

The above exception was the direct cause of the following exception:

Traceback (most recent call last):
  File "D:\GitHub\personal\cybersecurity-ai-assistant\.venv\Lib\site-packages\elastic_transport\_node\_http_urllib3.py", line 167, in perform_request
    response = self.pool.urlopen(
        method,
    ...<4 lines>...
        **kw,  # type: ignore[arg-type]
    )
  File "D:\GitHub\personal\cybersecurity-ai-assistant\.venv\Lib\site-packages\urllib3\connectionpool.py", line 841, in urlopen
    retries = retries.increment(
        method, url, error=new_e, _pool=self, _stacktrace=sys.exc_info()[2]
    )
  File "D:\GitHub\personal\cybersecurity-ai-assistant\.venv\Lib\site-packages\urllib3\util\retry.py", line 449, in increment
    raise reraise(type(error), error, _stacktrace)
          ~~~~~~~^^^^^^^^^^^^^^^^^^^^^^^^^^^^^^^^^
  File "D:\GitHub\personal\cybersecurity-ai-assistant\.venv\Lib\site-packages\urllib3\util\util.py", line 39, in reraise
    raise value
  File "D:\GitHub\personal\cybersecurity-ai-assistant\.venv\Lib\site-packages\urllib3\connectionpool.py", line 787, in urlopen
    response = self._make_request(
        conn,
    ...<10 lines>...
        **response_kw,
    )
  File "D:\GitHub\personal\cybersecurity-ai-assistant\.venv\Lib\site-packages\urllib3\connectionpool.py", line 493, in _make_request
    conn.request(
    ~~~~~~~~~~~~^
        method,
        ^^^^^^^
    ...<6 lines>...
        enforce_content_length=enforce_content_length,
        ^^^^^^^^^^^^^^^^^^^^^^^^^^^^^^^^^^^^^^^^^^^^^^
    )
    ^
  File "D:\GitHub\personal\cybersecurity-ai-assistant\.venv\Lib\site-packages\urllib3\connection.py", line 445, in request
    self.endheaders()
    ~~~~~~~~~~~~~~~^^
  File "C:\Users\igorv\AppData\Roaming\uv\python\cpython-3.13.2-windows-x86_64-none\Lib\http\client.py", line 1333, in endheaders
    self._send_output(message_body, encode_chunked=encode_chunked)
    ~~~~~~~~~~~~~~~~~^^^^^^^^^^^^^^^^^^^^^^^^^^^^^^^^^^^^^^^^^^^^^
  File "C:\Users\igorv\AppData\Roaming\uv\python\cpython-3.13.2-windows-x86_64-none\Lib\http\client.py", line 1093, in _send_output
    self.send(msg)
    ~~~~~~~~~^^^^^
  File "C:\Users\igorv\AppData\Roaming\uv\python\cpython-3.13.2-windows-x86_64-none\Lib\http\client.py", line 1037, in send
    self.connect()
    ~~~~~~~~~~~~^^
  File "D:\GitHub\personal\cybersecurity-ai-assistant\.venv\Lib\site-packages\urllib3\connection.py", line 276, in connect
    self.sock = self._new_conn()
                ~~~~~~~~~~~~~~^^
  File "D:\GitHub\personal\cybersecurity-ai-assistant\.venv\Lib\site-packages\urllib3\connection.py", line 205, in _new_conn
    raise NameResolutionError(self.host, self, e) from e
urllib3.exceptions.NameResolutionError: <urllib3.connection.HTTPConnection object at 0x000001CF12975F20>: Failed to resolve 'localhosthttps://b2e7e5b202d84e938f7e48f40dd02ef2.us-central1.gcp.cloud.es.io:443' ([Errno 11001] getaddrinfo failed)

The above exception was the direct cause of the following exception:

Traceback (most recent call last):
  File "D:\GitHub\personal\cybersecurity-ai-assistant\.venv\Lib\site-packages\elastic_transport\_transport.py", line 342, in perform_request
    resp = node.perform_request(
        method,
    ...<3 lines>...
        request_timeout=request_timeout,
    )
  File "D:\GitHub\personal\cybersecurity-ai-assistant\.venv\Lib\site-packages\elastic_transport\_node\_http_urllib3.py", line 202, in perform_request
    raise err from e
elastic_transport.ConnectionError: Connection error caused by: NameResolutionError(<urllib3.connection.HTTPConnection object at 0x000001CF12975F20>: Failed to resolve 'localhosthttps://b2e7e5b202d84e938f7e48f40dd02ef2.us-central1.gcp.cloud.es.io:443' ([Errno 11001] getaddrinfo failed))
2025-03-01 09:10:07,340 - elastic_transport.transport - INFO - POST http://[localhosthttps://b2e7e5b202d84e938f7e48f40dd02ef2.us-central1.gcp.cloud.es.io:443]:9200/ssh-honeypot/_doc [status:N/A duration:0.000s]
2025-03-01 09:10:07,340 - elastic_transport.node_pool - WARNING - Node <Urllib3HttpNode(http://[localhosthttps://b2e7e5b202d84e938f7e48f40dd02ef2.us-central1.gcp.cloud.es.io:443]:9200)> has failed for 2 times in a row, putting on 2 second timeout
2025-03-01 09:10:07,341 - elastic_transport.transport - WARNING - Retrying request after failure (attempt 1 of 3)
Traceback (most recent call last):
  File "D:\GitHub\personal\cybersecurity-ai-assistant\.venv\Lib\site-packages\urllib3\connection.py", line 198, in _new_conn
    sock = connection.create_connection(
        (self._dns_host, self.port),
    ...<2 lines>...
        socket_options=self.socket_options,
    )
  File "D:\GitHub\personal\cybersecurity-ai-assistant\.venv\Lib\site-packages\urllib3\util\connection.py", line 60, in create_connection
    for res in socket.getaddrinfo(host, port, family, socket.SOCK_STREAM):
               ~~~~~~~~~~~~~~~~~~^^^^^^^^^^^^^^^^^^^^^^^^^^^^^^^^^^^^^^^^
  File "C:\Users\igorv\AppData\Roaming\uv\python\cpython-3.13.2-windows-x86_64-none\Lib\socket.py", line 977, in getaddrinfo
    for res in _socket.getaddrinfo(host, port, family, type, proto, flags):
               ~~~~~~~~~~~~~~~~~~~^^^^^^^^^^^^^^^^^^^^^^^^^^^^^^^^^^^^^^^^
socket.gaierror: [Errno 11001] getaddrinfo failed

The above exception was the direct cause of the following exception:

Traceback (most recent call last):
  File "D:\GitHub\personal\cybersecurity-ai-assistant\.venv\Lib\site-packages\elastic_transport\_node\_http_urllib3.py", line 167, in perform_request
    response = self.pool.urlopen(
        method,
    ...<4 lines>...
        **kw,  # type: ignore[arg-type]
    )
  File "D:\GitHub\personal\cybersecurity-ai-assistant\.venv\Lib\site-packages\urllib3\connectionpool.py", line 841, in urlopen
    retries = retries.increment(
        method, url, error=new_e, _pool=self, _stacktrace=sys.exc_info()[2]
    )
  File "D:\GitHub\personal\cybersecurity-ai-assistant\.venv\Lib\site-packages\urllib3\util\retry.py", line 449, in increment
    raise reraise(type(error), error, _stacktrace)
          ~~~~~~~^^^^^^^^^^^^^^^^^^^^^^^^^^^^^^^^^
  File "D:\GitHub\personal\cybersecurity-ai-assistant\.venv\Lib\site-packages\urllib3\util\util.py", line 39, in reraise
    raise value
  File "D:\GitHub\personal\cybersecurity-ai-assistant\.venv\Lib\site-packages\urllib3\connectionpool.py", line 787, in urlopen
    response = self._make_request(
        conn,
    ...<10 lines>...
        **response_kw,
    )
  File "D:\GitHub\personal\cybersecurity-ai-assistant\.venv\Lib\site-packages\urllib3\connectionpool.py", line 493, in _make_request
    conn.request(
    ~~~~~~~~~~~~^
        method,
        ^^^^^^^
    ...<6 lines>...
        enforce_content_length=enforce_content_length,
        ^^^^^^^^^^^^^^^^^^^^^^^^^^^^^^^^^^^^^^^^^^^^^^
    )
    ^
  File "D:\GitHub\personal\cybersecurity-ai-assistant\.venv\Lib\site-packages\urllib3\connection.py", line 445, in request
    self.endheaders()
    ~~~~~~~~~~~~~~~^^
  File "C:\Users\igorv\AppData\Roaming\uv\python\cpython-3.13.2-windows-x86_64-none\Lib\http\client.py", line 1333, in endheaders
    self._send_output(message_body, encode_chunked=encode_chunked)
    ~~~~~~~~~~~~~~~~~^^^^^^^^^^^^^^^^^^^^^^^^^^^^^^^^^^^^^^^^^^^^^
  File "C:\Users\igorv\AppData\Roaming\uv\python\cpython-3.13.2-windows-x86_64-none\Lib\http\client.py", line 1093, in _send_output
    self.send(msg)
    ~~~~~~~~~^^^^^
  File "C:\Users\igorv\AppData\Roaming\uv\python\cpython-3.13.2-windows-x86_64-none\Lib\http\client.py", line 1037, in send
    self.connect()
    ~~~~~~~~~~~~^^
  File "D:\GitHub\personal\cybersecurity-ai-assistant\.venv\Lib\site-packages\urllib3\connection.py", line 276, in connect
    self.sock = self._new_conn()
                ~~~~~~~~~~~~~~^^
  File "D:\GitHub\personal\cybersecurity-ai-assistant\.venv\Lib\site-packages\urllib3\connection.py", line 205, in _new_conn
    raise NameResolutionError(self.host, self, e) from e
urllib3.exceptions.NameResolutionError: <urllib3.connection.HTTPConnection object at 0x000001CF12976140>: Failed to resolve 'localhosthttps://b2e7e5b202d84e938f7e48f40dd02ef2.us-central1.gcp.cloud.es.io:443' ([Errno 11001] getaddrinfo failed)

The above exception was the direct cause of the following exception:

Traceback (most recent call last):
  File "D:\GitHub\personal\cybersecurity-ai-assistant\.venv\Lib\site-packages\elastic_transport\_transport.py", line 342, in perform_request
    resp = node.perform_request(
        method,
    ...<3 lines>...
        request_timeout=request_timeout,
    )
  File "D:\GitHub\personal\cybersecurity-ai-assistant\.venv\Lib\site-packages\elastic_transport\_node\_http_urllib3.py", line 202, in perform_request
    raise err from e
elastic_transport.ConnectionError: Connection error caused by: NameResolutionError(<urllib3.connection.HTTPConnection object at 0x000001CF12976140>: Failed to resolve 'localhosthttps://b2e7e5b202d84e938f7e48f40dd02ef2.us-central1.gcp.cloud.es.io:443' ([Errno 11001] getaddrinfo failed))
2025-03-01 09:10:07,344 - elastic_transport.transport - INFO - POST http://[localhosthttps://b2e7e5b202d84e938f7e48f40dd02ef2.us-central1.gcp.cloud.es.io:443]:9200/ssh-honeypot/_doc [status:N/A duration:0.000s]
2025-03-01 09:10:07,344 - elastic_transport.node_pool - WARNING - Node <Urllib3HttpNode(http://[localhosthttps://b2e7e5b202d84e938f7e48f40dd02ef2.us-central1.gcp.cloud.es.io:443]:9200)> has failed for 3 times in a row, putting on 4 second timeout
2025-03-01 09:10:07,344 - elastic_transport.transport - WARNING - Retrying request after failure (attempt 2 of 3)
Traceback (most recent call last):
  File "D:\GitHub\personal\cybersecurity-ai-assistant\.venv\Lib\site-packages\urllib3\connection.py", line 198, in _new_conn
    sock = connection.create_connection(
        (self._dns_host, self.port),
    ...<2 lines>...
        socket_options=self.socket_options,
    )
  File "D:\GitHub\personal\cybersecurity-ai-assistant\.venv\Lib\site-packages\urllib3\util\connection.py", line 60, in create_connection
    for res in socket.getaddrinfo(host, port, family, socket.SOCK_STREAM):
               ~~~~~~~~~~~~~~~~~~^^^^^^^^^^^^^^^^^^^^^^^^^^^^^^^^^^^^^^^^
  File "C:\Users\igorv\AppData\Roaming\uv\python\cpython-3.13.2-windows-x86_64-none\Lib\socket.py", line 977, in getaddrinfo
    for res in _socket.getaddrinfo(host, port, family, type, proto, flags):
               ~~~~~~~~~~~~~~~~~~~^^^^^^^^^^^^^^^^^^^^^^^^^^^^^^^^^^^^^^^^
socket.gaierror: [Errno 11001] getaddrinfo failed

The above exception was the direct cause of the following exception:

Traceback (most recent call last):
  File "D:\GitHub\personal\cybersecurity-ai-assistant\.venv\Lib\site-packages\elastic_transport\_node\_http_urllib3.py", line 167, in perform_request
    response = self.pool.urlopen(
        method,
    ...<4 lines>...
        **kw,  # type: ignore[arg-type]
    )
  File "D:\GitHub\personal\cybersecurity-ai-assistant\.venv\Lib\site-packages\urllib3\connectionpool.py", line 841, in urlopen
    retries = retries.increment(
        method, url, error=new_e, _pool=self, _stacktrace=sys.exc_info()[2]
    )
  File "D:\GitHub\personal\cybersecurity-ai-assistant\.venv\Lib\site-packages\urllib3\util\retry.py", line 449, in increment
    raise reraise(type(error), error, _stacktrace)
          ~~~~~~~^^^^^^^^^^^^^^^^^^^^^^^^^^^^^^^^^
  File "D:\GitHub\personal\cybersecurity-ai-assistant\.venv\Lib\site-packages\urllib3\util\util.py", line 39, in reraise
    raise value
  File "D:\GitHub\personal\cybersecurity-ai-assistant\.venv\Lib\site-packages\urllib3\connectionpool.py", line 787, in urlopen
    response = self._make_request(
        conn,
    ...<10 lines>...
        **response_kw,
    )
  File "D:\GitHub\personal\cybersecurity-ai-assistant\.venv\Lib\site-packages\urllib3\connectionpool.py", line 493, in _make_request
    conn.request(
    ~~~~~~~~~~~~^
        method,
        ^^^^^^^
    ...<6 lines>...
        enforce_content_length=enforce_content_length,
        ^^^^^^^^^^^^^^^^^^^^^^^^^^^^^^^^^^^^^^^^^^^^^^
    )
    ^
  File "D:\GitHub\personal\cybersecurity-ai-assistant\.venv\Lib\site-packages\urllib3\connection.py", line 445, in request
    self.endheaders()
    ~~~~~~~~~~~~~~~^^
  File "C:\Users\igorv\AppData\Roaming\uv\python\cpython-3.13.2-windows-x86_64-none\Lib\http\client.py", line 1333, in endheaders
    self._send_output(message_body, encode_chunked=encode_chunked)
    ~~~~~~~~~~~~~~~~~^^^^^^^^^^^^^^^^^^^^^^^^^^^^^^^^^^^^^^^^^^^^^
  File "C:\Users\igorv\AppData\Roaming\uv\python\cpython-3.13.2-windows-x86_64-none\Lib\http\client.py", line 1093, in _send_output
    self.send(msg)
    ~~~~~~~~~^^^^^
  File "C:\Users\igorv\AppData\Roaming\uv\python\cpython-3.13.2-windows-x86_64-none\Lib\http\client.py", line 1037, in send
    self.connect()
    ~~~~~~~~~~~~^^
  File "D:\GitHub\personal\cybersecurity-ai-assistant\.venv\Lib\site-packages\urllib3\connection.py", line 276, in connect
    self.sock = self._new_conn()
                ~~~~~~~~~~~~~~^^
  File "D:\GitHub\personal\cybersecurity-ai-assistant\.venv\Lib\site-packages\urllib3\connection.py", line 205, in _new_conn
    raise NameResolutionError(self.host, self, e) from e
urllib3.exceptions.NameResolutionError: <urllib3.connection.HTTPConnection object at 0x000001CF12976250>: Failed to resolve 'localhosthttps://b2e7e5b202d84e938f7e48f40dd02ef2.us-central1.gcp.cloud.es.io:443' ([Errno 11001] getaddrinfo failed)

The above exception was the direct cause of the following exception:

Traceback (most recent call last):
  File "D:\GitHub\personal\cybersecurity-ai-assistant\.venv\Lib\site-packages\elastic_transport\_transport.py", line 342, in perform_request
    resp = node.perform_request(
        method,
    ...<3 lines>...
        request_timeout=request_timeout,
    )
  File "D:\GitHub\personal\cybersecurity-ai-assistant\.venv\Lib\site-packages\elastic_transport\_node\_http_urllib3.py", line 202, in perform_request
    raise err from e
elastic_transport.ConnectionError: Connection error caused by: NameResolutionError(<urllib3.connection.HTTPConnection object at 0x000001CF12976250>: Failed to resolve 'localhosthttps://b2e7e5b202d84e938f7e48f40dd02ef2.us-central1.gcp.cloud.es.io:443' ([Errno 11001] getaddrinfo failed))
2025-03-01 09:10:07,347 - elastic_transport.transport - INFO - POST http://[localhosthttps://b2e7e5b202d84e938f7e48f40dd02ef2.us-central1.gcp.cloud.es.io:443]:9200/ssh-honeypot/_doc [status:N/A duration:0.000s]
2025-03-01 09:10:07,347 - elastic_transport.node_pool - WARNING - Node <Urllib3HttpNode(http://[localhosthttps://b2e7e5b202d84e938f7e48f40dd02ef2.us-central1.gcp.cloud.es.io:443]:9200)> has failed for 4 times in a row, putting on 8 second timeout
2025-03-01 09:10:07,347 - ssh-honeypot - ERROR - Failed to send log to Elasticsearch: Connection error caused by: ConnectionError(Connection error caused by: NameResolutionError(<urllib3.connection.HTTPConnection object at 0x000001CF12975F20>: Failed to resolve 'localhosthttps://b2e7e5b202d84e938f7e48f40dd02ef2.us-central1.gcp.cloud.es.io:443' ([Errno 11001] getaddrinfo failed)))
2025-03-01 09:10:07,347 - paramiko.transport - INFO - Auth rejected (password).
2025-03-01 09:10:07,350 - paramiko.transport - ERROR - Socket exception: An existing connection was forcibly closed by the remote host (10054)
2025-03-01 09:10:07,350 - ssh-honeypot - INFO - No channel from 127.0.0.1:51156
2025-03-01 09:10:12,154 - ssh-honeypot - INFO - Received shutdown signal
2025-03-01 09:10:12,155 - ssh-honeypot - INFO - SSH Honeypot shutting down
